Workbook

Sheet Como usar
B1: Controle financeiro · Porta Studio
B2: Planilha para acompanhar, mês a mês, o que entrou, o que saiu e quanto sobrou.
B4: Legenda
C5: Exemplo | D5: Célula amarela com texto azul: você preenche.
C6: Exemplo | D6: Célula cinza: calcula sozinha. Não precisa mexer.
C7: Triângulo vermelho | D7: Os títulos com um triângulo no canto têm uma explicação: passe o mouse ou toque neles.
B9: Passo a passo
B10: 1 | C10: Lançamentos | D10: Tudo que entrou ou saiu de dinheiro, uma linha por movimento: entrada de cliente, assinatura de IA, domínio, Shopify, anúncio. Escolha a categoria e o tipo (Entrada ou Saída) aparece sozinho. O valor é sempre positivo.
B11: 2 | C11: Projetos | D11: Cada cliente fechado, com o valor combinado. Use o mesmo nome do projeto nos lançamentos e a planilha mostra quanto já recebeu, quanto falta receber e quanto sobrou.
B12: 3 | C12: Custos fixos | D12: As assinaturas do negócio (IA, domínio, Shopify, hospedagem). Mostra quanto o negócio custa por mês, já convertendo dólar para real. Atualize a cotação de vez em quando. Quando a cobrança cair no cartão, lance também em Lançamentos.
B13: 4 | C13: Painel | D13: Escolha o mês na célula amarela e veja quanto entrou, saiu, o lucro, quanto falta receber e para onde foi o dinheiro.
B14: 5 | C14: Resumo mensal | D14: Os 12 meses lado a lado, por categoria. Para começar um ano novo, troque o primeiro mês (ou salve uma cópia do arquivo).
B15: 6 | C15: Tabela de preços | D15: Os preços do catálogo com as horas de cada pacote. Mostra quanto sobra por hora e avisa quando um pacote fica abaixo do seu mínimo.
B16: 7 | C16: Listas | D16: As categorias e as formas de pagamento dos menus. Para criar uma categoria nova, escreva no fim da lista e escolha se é Entrada ou Saída.
B18: Antes de começar
C19: • | D19: Apague as linhas marcadas com EXEMPLO nas abas Lançamentos e Projetos.
C20: • | D20: Confira os valores da aba Custos fixos com as suas faturas e marque Sim só no que você assina.
C21: • | D21: Lance as coisas no dia em que o dinheiro entra ou sai. No fim do mês, o Painel já está pronto.

Sheet Painel
B1: Painel financeiro · Porta Studio
B2: Escolha o mês na célula amarela. Tudo aqui é calculado a partir das outras abas.
B4: Mês de referência | C4: 46327
B6: No mês escolhido
B7: Entrou | E7: Saiu | H7: Lucro do mês | K7: Margem
B8: =SUMIFS(Lançamentos!$G$5:$G$1004,Lançamentos!$C$5:$C$1004,"Entrada",Lançamentos!$H$5:$H$1004,$C$4) -> 600 | E8: =SUMIFS(Lançamentos!$G$5:$G$1004,Lançamentos!$C$5:$C$1004,"Saída",Lançamentos!$H$5:$H$1004,$C$4) -> 114 | H8: =B8-E8 -> 486 | K8: =IF(B8>0,H8/B8,0) -> 0.81
B9: Entradas lançadas no mês | E9: Saídas lançadas no mês | H9: Entrou menos saiu | K9: Quanto sobra de cada R$ 100
B11: Visão geral
B12: Lucro nos 12 meses | E12: A receber de clientes | H12: Custos fixos por mês | K12: Mensalidades de clientes
B13: ='Resumo mensal'!E19 -> 486 | E13: =SUM(Projetos!J5:J204) -> 600 | H13: ='Custos fixos'!H4 -> 339.19083 | K13: =SUMIFS(Projetos!M5:M204,Projetos!G5:G204,"Em produção")+SUMIFS(Projetos!M5:M204,Projetos!G5:G204,"Entregue") -> 90
B14: Período da aba Resumo mensal | E14: Projetos em produção e entregues | H14: Assinaturas ativas, em reais | K14: Recorrente que entra todo mês
B16: Para onde foi o dinheiro no mês | E16: De onde veio o dinheiro no mês
B17: Categoria de saída | C17: Valor | E17: Categoria de entrada | F17: Valor
B18: =IFERROR(INDEX(Listas!$B$5:$B$40,MATCH(ROWS($B$18:B18),Listas!$E$5:$E$40,0)),"") -> Inteligência artificial | C18: =IF(B18="","",SUMIFS(Lançamentos!$G$5:$G$1004,Lançamentos!$B$5:$B$1004,B18,Lançamentos!$H$5:$H$1004,$C$4)) -> 114 | E18: =IFERROR(INDEX(Listas!$B$5:$B$40,MATCH(ROWS($E$18:E18),Listas!$D$5:$D$40,0)),"") -> Site WhatsApp | F18: =IF(E18="","",SUMIFS(Lançamentos!$G$5:$G$1004,Lançamentos!$B$5:$B$1004,E18,Lançamentos!$H$5:$H$1004,$C$4)) -> 600
B19: =IFERROR(INDEX(Listas!$B$5:$B$40,MATCH(ROWS($B$18:B19),Listas!$E$5:$E$40,0)),"") -> Domínios | C19: =IF(B19="","",SUMIFS(Lançamentos!$G$5:$G$1004,Lançamentos!$B$5:$B$1004,B19,Lançamentos!$H$5:$H$1004,$C$4)) -> 0 | E19: =IFERROR(INDEX(Listas!$B$5:$B$40,MATCH(ROWS($E$18:E19),Listas!$D$5:$D$40,0)),"") -> Loja virtual | F19: =IF(E19="","",SUMIFS(Lançamentos!$G$5:$G$1004,Lançamentos!$B$5:$B$1004,E19,Lançamentos!$H$5:$H$1004,$C$4)) -> 0
B20: =IFERROR(INDEX(Listas!$B$5:$B$40,MATCH(ROWS($B$18:B20),Listas!$E$5:$E$40,0)),"") -> Hospedagem | C20: =IF(B20="","",SUMIFS(Lançamentos!$G$5:$G$1004,Lançamentos!$B$5:$B$1004,B20,Lançamentos!$H$5:$H$1004,$C$4)) -> 0 | E20: =IFERROR(INDEX(Listas!$B$5:$B$40,MATCH(ROWS($E$18:E20),Listas!$D$5:$D$40,0)),"") -> SaaS / sistema | F20: =IF(E20="","",SUMIFS(Lançamentos!$G$5:$G$1004,Lançamentos!$B$5:$B$1004,E20,Lançamentos!$H$5:$H$1004,$C$4)) -> 0
B21: =IFERROR(INDEX(Listas!$B$5:$B$40,MATCH(ROWS($B$18:B21),Listas!$E$5:$E$40,0)),"") -> Shopify e plataformas | C21: =IF(B21="","",SUMIFS(Lançamentos!$G$5:$G$1004,Lançamentos!$B$5:$B$1004,B21,Lançamentos!$H$5:$H$1004,$C$4)) -> 0 | E21: =IFERROR(INDEX(Listas!$B$5:$B$40,MATCH(ROWS($E$18:E21),Listas!$D$5:$D$40,0)),"") -> Mensalidade de cliente | F21: =IF(E21="","",SUMIFS(Lançamentos!$G$5:$G$1004,Lançamentos!$B$5:$B$1004,E21,Lançamentos!$H$5:$H$1004,$C$4)) -> 0
B22: =IFERROR(INDEX(Listas!$B$5:$B$40,MATCH(ROWS($B$18:B22),Listas!$E$5:$E$40,0)),"") -> Ferramentas e apps | C22: =IF(B22="","",SUMIFS(Lançamentos!$G$5:$G$1004,Lançamentos!$B$5:$B$1004,B22,Lançamentos!$H$5:$H$1004,$C$4)) -> 0 | E22: =IFERROR(INDEX(Listas!$B$5:$B$40,MATCH(ROWS($E$18:E22),Listas!$D$5:$D$40,0)),"") -> Extras e ajustes | F22: =IF(E22="","",SUMIFS(Lançamentos!$G$5:$G$1004,Lançamentos!$B$5:$B$1004,E22,Lançamentos!$H$5:$H$1004,$C$4)) -> 0
B23: =IFERROR(INDEX(Listas!$B$5:$B$40,MATCH(ROWS($B$18:B23),Listas!$E$5:$E$40,0)),"") -> Anúncios e marketing | C23: =IF(B23="","",SUMIFS(Lançamentos!$G$5:$G$1004,Lançamentos!$B$5:$B$1004,B23,Lançamentos!$H$5:$H$1004,$C$4)) -> 0 | E23: =IFERROR(INDEX(Listas!$B$5:$B$40,MATCH(ROWS($E$18:E23),Listas!$D$5:$D$40,0)),"") -> Repasse de domínio | F23: =IF(E23="","",SUMIFS(Lançamentos!$G$5:$G$1004,Lançamentos!$B$5:$B$1004,E23,Lançamentos!$H$5:$H$1004,$C$4)) -> 0
B24: =IFERROR(INDEX(Listas!$B$5:$B$40,MATCH(ROWS($B$18:B24),Listas!$E$5:$E$40,0)),"") -> Impostos (MEI / DAS) | C24: =IF(B24="","",SUMIFS(Lançamentos!$G$5:$G$1004,Lançamentos!$B$5:$B$1004,B24,Lançamentos!$H$5:$H$1004,$C$4)) -> 0 | E24: =IFERROR(INDEX(Listas!$B$5:$B$40,MATCH(ROWS($E$18:E24),Listas!$D$5:$D$40,0)),"") -> Outras entradas | F24: =IF(E24="","",SUMIFS(Lançamentos!$G$5:$G$1004,Lançamentos!$B$5:$B$1004,E24,Lançamentos!$H$5:$H$1004,$C$4)) -> 0
B25: =IFERROR(INDEX(Listas!$B$5:$B$40,MATCH(ROWS($B$18:B25),Listas!$E$5:$E$40,0)),"") -> Taxas de pagamento | C25: =IF(B25="","",SUMIFS(Lançamentos!$G$5:$G$1004,Lançamentos!$B$5:$B$1004,B25,Lançamentos!$H$5:$H$1004,$C$4)) -> 0 | E25: =IFERROR(INDEX(Listas!$B$5:$B$40,MATCH(ROWS($E$18:E25),Listas!$D$5:$D$40,0)),"") | F25: =IF(E25="","",SUMIFS(Lançamentos!$G$5:$G$1004,Lançamentos!$B$5:$B$1004,E25,Lançamentos!$H$5:$H$1004,$C$4))
B26: =IFERROR(INDEX(Listas!$B$5:$B$40,MATCH(ROWS($B$18:B26),Listas!$E$5:$E$40,0)),"") -> Freelancers e terceiros | C26: =IF(B26="","",SUMIFS(Lançamentos!$G$5:$G$1004,Lançamentos!$B$5:$B$1004,B26,Lançamentos!$H$5:$H$1004,$C$4)) -> 0 | E26: Total | F26: =SUM(F18:F25) -> 600
B27: =IFERROR(INDEX(Listas!$B$5:$B$40,MATCH(ROWS($B$18:B27),Listas!$E$5:$E$40,0)),"") -> Equipamentos | C27: =IF(B27="","",SUMIFS(Lançamentos!$G$5:$G$1004,Lançamentos!$B$5:$B$1004,B27,Lançamentos!$H$5:$H$1004,$C$4)) -> 0
B28: =IFERROR(INDEX(Listas!$B$5:$B$40,MATCH(ROWS($B$18:B28),Listas!$E$5:$E$40,0)),"") -> Internet e celular | C28: =IF(B28="","",SUMIFS(Lançamentos!$G$5:$G$1004,Lançamentos!$B$5:$B$1004,B28,Lançamentos!$H$5:$H$1004,$C$4)) -> 0
B29: =IFERROR(INDEX(Listas!$B$5:$B$40,MATCH(ROWS($B$18:B29),Listas!$E$5:$E$40,0)),"") -> Outras saídas | C29: =IF(B29="","",SUMIFS(Lançamentos!$G$5:$G$1004,Lançamentos!$B$5:$B$1004,B29,Lançamentos!$H$5:$H$1004,$C$4)) -> 0
B30: =IFERROR(INDEX(Listas!$B$5:$B$40,MATCH(ROWS($B$18:B30),Listas!$E$5:$E$40,0)),"") | C30: =IF(B30="","",SUMIFS(Lançamentos!$G$5:$G$1004,Lançamentos!$B$5:$B$1004,B30,Lançamentos!$H$5:$H$1004,$C$4))
B31: =IFERROR(INDEX(Listas!$B$5:$B$40,MATCH(ROWS($B$18:B31),Listas!$E$5:$E$40,0)),"") | C31: =IF(B31="","",SUMIFS(Lançamentos!$G$5:$G$1004,Lançamentos!$B$5:$B$1004,B31,Lançamentos!$H$5:$H$1004,$C$4))
B32: Total | C32: =SUM(C18:C31) -> 114

Sheet Lançamentos
A1: Lançamentos
A2: Tudo que entrou ou saiu de dinheiro, uma linha por movimento. Amarelo: você preenche. Cinza: calcula sozinho.
A3: Escolha a categoria e o tipo (Entrada ou Saída) aparece sozinho. Digite o valor sempre positivo.
A4: Data | B4: Categoria | C4: Tipo | D4: Descrição | E4: Projeto (opcional) | F4: Forma de pagamento | G4: Valor (R$) | H4: Mês
A5: 46329 | B5: Site WhatsApp | C5: =IF(B5="","",IFERROR(INDEX(Listas!$C$5:$C$40,MATCH(B5,Listas!$B$5:$B$40,0)),"?")) -> Entrada | D5: EXEMPLO · entrada de 50% do site (apague esta linha) | E5: EXEMPLO · Hamburgueria | F5: Pix | G5: 600 | H5: =IF(A5="","",DATE(YEAR(A5),MONTH(A5),1)) -> 46327
A6: 46331 | B6: Inteligência artificial | C6: =IF(B6="","",IFERROR(INDEX(Listas!$C$5:$C$40,MATCH(B6,Listas!$B$5:$B$40,0)),"?")) -> Saída | D6: EXEMPLO · assinatura Claude Pro (apague esta linha) | F6: Cartão de crédito | G6: 114 | H6: =IF(A6="","",DATE(YEAR(A6),MONTH(A6),1)) -> 46327
C7: =IF(B7="","",IFERROR(INDEX(Listas!$C$5:$C$40,MATCH(B7,Listas!$B$5:$B$40,0)),"?")) | H7: =IF(A7="","",DATE(YEAR(A7),MONTH(A7),1))
C8: =IF(B8="","",IFERROR(INDEX(Listas!$C$5:$C$40,MATCH(B8,Listas!$B$5:$B$40,0)),"?")) | H8: =IF(A8="","",DATE(YEAR(A8),MONTH(A8),1))
C9: =IF(B9="","",IFERROR(INDEX(Listas!$C$5:$C$40,MATCH(B9,Listas!$B$5:$B$40,0)),"?")) | H9: =IF(A9="","",DATE(YEAR(A9),MONTH(A9),1))
C10: =IF(B10="","",IFERROR(INDEX(Listas!$C$5:$C$40,MATCH(B10,Listas!$B$5:$B$40,0)),"?")) | H10: =IF(A10="","",DATE(YEAR(A10),MONTH(A10),1))
C11: =IF(B11="","",IFERROR(INDEX(Listas!$C$5:$C$40,MATCH(B11,Listas!$B$5:$B$40,0)),"?")) | H11: =IF(A11="","",DATE(YEAR(A11),MONTH(A11),1))
C12: =IF(B12="","",IFERROR(INDEX(Listas!$C$5:$C$40,MATCH(B12,Listas!$B$5:$B$40,0)),"?")) | H12: =IF(A12="","",DATE(YEAR(A12),MONTH(A12),1))
C13: =IF(B13="","",IFERROR(INDEX(Listas!$C$5:$C$40,MATCH(B13,Listas!$B$5:$B$40,0)),"?")) | H13: =IF(A13="","",DATE(YEAR(A13),MONTH(A13),1))
C14: =IF(B14="","",IFERROR(INDEX(Listas!$C$5:$C$40,MATCH(B14,Listas!$B$5:$B$40,0)),"?")) | H14: =IF(A14="","",DATE(YEAR(A14),MONTH(A14),1))
C15: =IF(B15="","",IFERROR(INDEX(Listas!$C$5:$C$40,MATCH(B15,Listas!$B$5:$B$40,0)),"?")) | H15: =IF(A15="","",DATE(YEAR(A15),MONTH(A15),1))
C16: =IF(B16="","",IFERROR(INDEX(Listas!$C$5:$C$40,MATCH(B16,Listas!$B$5:$B$40,0)),"?")) | H16: =IF(A16="","",DATE(YEAR(A16),MONTH(A16),1))
C17: =IF(B17="","",IFERROR(INDEX(Listas!$C$5:$C$40,MATCH(B17,Listas!$B$5:$B$40,0)),"?")) | H17: =IF(A17="","",DATE(YEAR(A17),MONTH(A17),1))
C18: =IF(B18="","",IFERROR(INDEX(Listas!$C$5:$C$40,MATCH(B18,Listas!$B$5:$B$40,0)),"?")) | H18: =IF(A18="","",DATE(YEAR(A18),MONTH(A18),1))
... C1004: =IF(B1004="","",IFERROR(INDEX(Listas!$C$5:$C$40,MATCH(B1004,Listas!$B$5:$B$40,0)),"?")) | H1004: =IF(A1004="","",DATE(YEAR(A1004),MONTH(A1004),1))

Sheet Projetos
A1: Projetos e clientes
A2: Cada cliente fechado. O recebido e os custos vêm sozinhos dos lançamentos com o mesmo nome de projeto.
G3: Totais | H3: =SUM(H5:H204) -> 1200 | I3: =SUM(I5:I204) -> 600 | J3: =SUM(J5:J204) -> 600 | K3: =SUM(K5:K204) -> 0 | L3: =SUM(L5:L204) -> 600 | M3: =SUM(M5:M204) -> 90
A4: Projeto (nome único) | B4: Cliente / contato | C4: Tipo | D4: Pacote | E4: Fechado em | F4: Entrega prevista | G4: Status | H4: Valor fechado (R$) | I4: Recebido (R$) | J4: A receber (R$) | K4: Custos do projeto (R$) | L4: Lucro até agora (R$) | M4: Mensalidade (R$/mês) | N4: Observações
A5: EXEMPLO · Hamburgueria | B5: Nome do dono · (62) 90000-0000 | C5: Site WhatsApp | D5: Completo | E5: 46329 | F5: 46341 | G5: Em produção | H5: 1200 | I5: =IF(A5="","",SUMIFS(Lançamentos!$G$5:$G$1004,Lançamentos!$E$5:$E$1004,A5,Lançamentos!$C$5:$C$1004,"Entrada")) -> 600 | J5: =IF(A5="","",IF(OR(G5="Em produção",G5="Entregue"),MAX(H5-I5,0),0)) -> 600 | K5: =IF(A5="","",SUMIFS(Lançamentos!$G$5:$G$1004,Lançamentos!$E$5:$E$1004,A5,Lançamentos!$C$5:$C$1004,"Saída")) -> 0 | L5: =IF(A5="","",I5-K5) -> 600 | M5: 90 | N5: Apague esta linha quando começar
I6: =IF(A6="","",SUMIFS(Lançamentos!$G$5:$G$1004,Lançamentos!$E$5:$E$1004,A6,Lançamentos!$C$5:$C$1004,"Entrada")) | J6: =IF(A6="","",IF(OR(G6="Em produção",G6="Entregue"),MAX(H6-I6,0),0)) | K6: =IF(A6="","",SUMIFS(Lançamentos!$G$5:$G$1004,Lançamentos!$E$5:$E$1004,A6,Lançamentos!$C$5:$C$1004,"Saída")) | L6: =IF(A6="","",I6-K6)
I7: =IF(A7="","",SUMIFS(Lançamentos!$G$5:$G$1004,Lançamentos!$E$5:$E$1004,A7,Lançamentos!$C$5:$C$1004,"Entrada")) | J7: =IF(A7="","",IF(OR(G7="Em produção",G7="Entregue"),MAX(H7-I7,0),0)) | K7: =IF(A7="","",SUMIFS(Lançamentos!$G$5:$G$1004,Lançamentos!$E$5:$E$1004,A7,Lançamentos!$C$5:$C$1004,"Saída")) | L7: =IF(A7="","",I7-K7)
I8: =IF(A8="","",SUMIFS(Lançamentos!$G$5:$G$1004,Lançamentos!$E$5:$E$1004,A8,Lançamentos!$C$5:$C$1004,"Entrada")) | J8: =IF(A8="","",IF(OR(G8="Em produção",G8="Entregue"),MAX(H8-I8,0),0)) | K8: =IF(A8="","",SUMIFS(Lançamentos!$G$5:$G$1004,Lançamentos!$E$5:$E$1004,A8,Lançamentos!$C$5:$C$1004,"Saída")) | L8: =IF(A8="","",I8-K8)
I9: =IF(A9="","",SUMIFS(Lançamentos!$G$5:$G$1004,Lançamentos!$E$5:$E$1004,A9,Lançamentos!$C$5:$C$1004,"Entrada")) | J9: =IF(A9="","",IF(OR(G9="Em produção",G9="Entregue"),MAX(H9-I9,0),0)) | K9: =IF(A9="","",SUMIFS(Lançamentos!$G$5:$G$1004,Lançamentos!$E$5:$E$1004,A9,Lançamentos!$C$5:$C$1004,"Saída")) | L9: =IF(A9="","",I9-K9)
I10: =IF(A10="","",SUMIFS(Lançamentos!$G$5:$G$1004,Lançamentos!$E$5:$E$1004,A10,Lançamentos!$C$5:$C$1004,"Entrada")) | J10: =IF(A10="","",IF(OR(G10="Em produção",G10="Entregue"),MAX(H10-I10,0),0)) | K10: =IF(A10="","",SUMIFS(Lançamentos!$G$5:$G$1004,Lançamentos!$E$5:$E$1004,A10,Lançamentos!$C$5:$C$1004,"Saída")) | L10: =IF(A10="","",I10-K10)
I11: =IF(A11="","",SUMIFS(Lançamentos!$G$5:$G$1004,Lançamentos!$E$5:$E$1004,A11,Lançamentos!$C$5:$C$1004,"Entrada")) | J11: =IF(A11="","",IF(OR(G11="Em produção",G11="Entregue"),MAX(H11-I11,0),0)) | K11: =IF(A11="","",SUMIFS(Lançamentos!$G$5:$G$1004,Lançamentos!$E$5:$E$1004,A11,Lançamentos!$C$5:$C$1004,"Saída")) | L11: =IF(A11="","",I11-K11)
I12: =IF(A12="","",SUMIFS(Lançamentos!$G$5:$G$1004,Lançamentos!$E$5:$E$1004,A12,Lançamentos!$C$5:$C$1004,"Entrada")) | J12: =IF(A12="","",IF(OR(G12="Em produção",G12="Entregue"),MAX(H12-I12,0),0)) | K12: =IF(A12="","",SUMIFS(Lançamentos!$G$5:$G$1004,Lançamentos!$E$5:$E$1004,A12,Lançamentos!$C$5:$C$1004,"Saída")) | L12: =IF(A12="","",I12-K12)
I13: =IF(A13="","",SUMIFS(Lançamentos!$G$5:$G$1004,Lançamentos!$E$5:$E$1004,A13,Lançamentos!$C$5:$C$1004,"Entrada")) | J13: =IF(A13="","",IF(OR(G13="Em produção",G13="Entregue"),MAX(H13-I13,0),0)) | K13: =IF(A13="","",SUMIFS(Lançamentos!$G$5:$G$1004,Lançamentos!$E$5:$E$1004,A13,Lançamentos!$C$5:$C$1004,"Saída")) | L13: =IF(A13="","",I13-K13)
I14: =IF(A14="","",SUMIFS(Lançamentos!$G$5:$G$1004,Lançamentos!$E$5:$E$1004,A14,Lançamentos!$C$5:$C$1004,"Entrada")) | J14: =IF(A14="","",IF(OR(G14="Em produção",G14="Entregue"),MAX(H14-I14,0),0)) | K14: =IF(A14="","",SUMIFS(Lançamentos!$G$5:$G$1004,Lançamentos!$E$5:$E$1004,A14,Lançamentos!$C$5:$C$1004,"Saída")) | L14: =IF(A14="","",I14-K14)
I15: =IF(A15="","",SUMIFS(Lançamentos!$G$5:$G$1004,Lançamentos!$E$5:$E$1004,A15,Lançamentos!$C$5:$C$1004,"Entrada")) | J15: =IF(A15="","",IF(OR(G15="Em produção",G15="Entregue"),MAX(H15-I15,0),0)) | K15: =IF(A15="","",SUMIFS(Lançamentos!$G$5:$G$1004,Lançamentos!$E$5:$E$1004,A15,Lançamentos!$C$5:$C$1004,"Saída")) | L15: =IF(A15="","",I15-K15)
I16: =IF(A16="","",SUMIFS(Lançamentos!$G$5:$G$1004,Lançamentos!$E$5:$E$1004,A16,Lançamentos!$C$5:$C$1004,"Entrada")) | J16: =IF(A16="","",IF(OR(G16="Em produção",G16="Entregue"),MAX(H16-I16,0),0)) | K16: =IF(A16="","",SUMIFS(Lançamentos!$G$5:$G$1004,Lançamentos!$E$5:$E$1004,A16,Lançamentos!$C$5:$C$1004,"Saída")) | L16: =IF(A16="","",I16-K16)
I17: =IF(A17="","",SUMIFS(Lançamentos!$G$5:$G$1004,Lançamentos!$E$5:$E$1004,A17,Lançamentos!$C$5:$C$1004,"Entrada")) | J17: =IF(A17="","",IF(OR(G17="Em produção",G17="Entregue"),MAX(H17-I17,0),0)) | K17: =IF(A17="","",SUMIFS(Lançamentos!$G$5:$G$1004,Lançamentos!$E$5:$E$1004,A17,Lançamentos!$C$5:$C$1004,"Saída")) | L17: =IF(A17="","",I17-K17)
... I204: =IF(A204="","",SUMIFS(Lançamentos!$G$5:$G$1004,Lançamentos!$E$5:$E$1004,A204,Lançamentos!$C$5:$C$1004,"Entrada")) | J204: =IF(A204="","",IF(OR(G204="Em produção",G204="Entregue"),MAX(H204-I204,0),0)) | K204: =IF(A204="","",SUMIFS(Lançamentos!$G$5:$G$1004,Lançamentos!$E$5:$E$1004,A204,Lançamentos!$C$5:$C$1004,"Saída")) | L204: =IF(A204="","",I204-K204)

Sheet Custos fixos
A1: Custos fixos e assinaturas
A2: IA, domínio, Shopify, hospedagem: quanto o negócio custa por mês. Quando a cobrança cair, lance também em Lançamentos.
A4: Cotação do dólar (R$) | B4: 5.5 | G4: Total por mês | H4: =SUM(H8:H37) -> 339.19083
A5: IOF em compra no exterior | B5: 0.035 | G5: Total por ano | H5: =SUM(I8:I37) -> 4070.29
A7: Ferramenta / serviço | B7: Categoria | C7: Moeda | D7: Valor cobrado | E7: Cobrança | F7: Dia da cobrança | G7: Ativo? | H7: Custo por mês (R$) | I7: Custo por ano (R$) | J7: Observação
A8: Claude Pro | B8: Inteligência artificial | C8: US$ | D8: 20 | E8: Mensal | G8: Sim | H8: =IF(OR(A8="",G8<>"Sim"),0,IF(C8="US$",D8*$B$4*(1+$B$5),D8)/IF(E8="Anual",12,1)) -> 113.85 | I8: =H8*12 -> 1366.2 | J8: Plano Pro (US$ 20/mês). Confira o valor na fatura.
A9: ChatGPT Plus | B9: Inteligência artificial | C9: US$ | D9: 20 | E9: Mensal | G9: Não | H9: =IF(OR(A9="",G9<>"Sim"),0,IF(C9="US$",D9*$B$4*(1+$B$5),D9)/IF(E9="Anual",12,1)) -> 0 | I9: =H9*12 -> 0 | J9: Marque Sim se assinar.
A10: Gerador de imagens e vídeos com IA | B10: Inteligência artificial | C10: US$ | E10: Mensal | G10: Sim | H10: =IF(OR(A10="",G10<>"Sim"),0,IF(C10="US$",D10*$B$4*(1+$B$5),D10)/IF(E10="Anual",12,1)) -> 0 | I10: =H10*12 -> 0 | J10: Ex.: Higgsfield. Preencha com o valor do seu plano.
A11: Domínio .com.br (Registro.br) | B11: Domínios | C11: R$ | D11: 40 | E11: Anual | G11: Sim | H11: =IF(OR(A11="",G11<>"Sim"),0,IF(C11="US$",D11*$B$4*(1+$B$5),D11)/IF(E11="Anual",12,1)) -> 3.3333333 | I11: =H11*12 -> 40 | J11: Cerca de R$ 40 por ano, como diz o seu site. Uma linha por domínio que você paga.
A12: Netlify (hospedagem dos sites) | B12: Hospedagem | C12: US$ | D12: 0 | E12: Mensal | G12: Sim | H12: =IF(OR(A12="",G12<>"Sim"),0,IF(C12="US$",D12*$B$4*(1+$B$5),D12)/IF(E12="Anual",12,1)) -> 0 | I12: =H12*12 -> 0 | J12: Plano grátis. Se mudar de plano, atualize o valor.
A13: Shopify Basic | B13: Shopify e plataformas | C13: US$ | D13: 39 | E13: Mensal | G13: Sim | H13: =IF(OR(A13="",G13<>"Sim"),0,IF(C13="US$",D13*$B$4*(1+$B$5),D13)/IF(E13="Anual",12,1)) -> 222.0075 | I13: =H13*12 -> 2664.09 | J13: US$ 39 no plano mensal ou US$ 29/mês no anual (preço público). Se a loja for do cliente, quem paga é ele.
A14: Canva Pro | B14: Ferramentas e apps | C14: R$ | E14: Mensal | G14: Não | H14: =IF(OR(A14="",G14<>"Sim"),0,IF(C14="US$",D14*$B$4*(1+$B$5),D14)/IF(E14="Anual",12,1)) -> 0 | I14: =H14*12 -> 0 | J14: Preencha o valor e marque Sim se assinar.
A15: DAS do MEI | B15: Impostos (MEI / DAS) | C15: R$ | E15: Mensal | G15: Não | H15: =IF(OR(A15="",G15<>"Sim"),0,IF(C15="US$",D15*$B$4*(1+$B$5),D15)/IF(E15="Anual",12,1)) -> 0 | I15: =H15*12 -> 0 | J15: Se você for MEI, coloque o valor do boleto mensal.
A16: Internet e celular | B16: Internet e celular | C16: R$ | E16: Mensal | G16: Não | H16: =IF(OR(A16="",G16<>"Sim"),0,IF(C16="US$",D16*$B$4*(1+$B$5),D16)/IF(E16="Anual",12,1)) -> 0 | I16: =H16*12 -> 0 | J16: Só a parte que você usa para o trabalho, se quiser contar.
H17: =IF(OR(A17="",G17<>"Sim"),0,IF(C17="US$",D17*$B$4*(1+$B$5),D17)/IF(E17="Anual",12,1)) -> 0 | I17: =H17*12 -> 0
H18: =IF(OR(A18="",G18<>"Sim"),0,IF(C18="US$",D18*$B$4*(1+$B$5),D18)/IF(E18="Anual",12,1)) -> 0 | I18: =H18*12 -> 0
H19: =IF(OR(A19="",G19<>"Sim"),0,IF(C19="US$",D19*$B$4*(1+$B$5),D19)/IF(E19="Anual",12,1)) -> 0 | I19: =H19*12 -> 0
H20: =IF(OR(A20="",G20<>"Sim"),0,IF(C20="US$",D20*$B$4*(1+$B$5),D20)/IF(E20="Anual",12,1)) -> 0 | I20: =H20*12 -> 0
H21: =IF(OR(A21="",G21<>"Sim"),0,IF(C21="US$",D21*$B$4*(1+$B$5),D21)/IF(E21="Anual",12,1)) -> 0 | I21: =H21*12 -> 0
H22: =IF(OR(A22="",G22<>"Sim"),0,IF(C22="US$",D22*$B$4*(1+$B$5),D22)/IF(E22="Anual",12,1)) -> 0 | I22: =H22*12 -> 0
H23: =IF(OR(A23="",G23<>"Sim"),0,IF(C23="US$",D23*$B$4*(1+$B$5),D23)/IF(E23="Anual",12,1)) -> 0 | I23: =H23*12 -> 0
H24: =IF(OR(A24="",G24<>"Sim"),0,IF(C24="US$",D24*$B$4*(1+$B$5),D24)/IF(E24="Anual",12,1)) -> 0 | I24: =H24*12 -> 0
H25: =IF(OR(A25="",G25<>"Sim"),0,IF(C25="US$",D25*$B$4*(1+$B$5),D25)/IF(E25="Anual",12,1)) -> 0 | I25: =H25*12 -> 0
H26: =IF(OR(A26="",G26<>"Sim"),0,IF(C26="US$",D26*$B$4*(1+$B$5),D26)/IF(E26="Anual",12,1)) -> 0 | I26: =H26*12 -> 0
H27: =IF(OR(A27="",G27<>"Sim"),0,IF(C27="US$",D27*$B$4*(1+$B$5),D27)/IF(E27="Anual",12,1)) -> 0 | I27: =H27*12 -> 0
H28: =IF(OR(A28="",G28<>"Sim"),0,IF(C28="US$",D28*$B$4*(1+$B$5),D28)/IF(E28="Anual",12,1)) -> 0 | I28: =H28*12 -> 0
... H37: =IF(OR(A37="",G37<>"Sim"),0,IF(C37="US$",D37*$B$4*(1+$B$5),D37)/IF(E37="Anual",12,1)) -> 0 | I37: =H37*12 -> 0

Sheet Resumo mensal
B1: Resumo mensal
B2: Os 12 meses lado a lado, calculados a partir dos lançamentos. Para começar outro ano, troque o primeiro mês.
B4: Primeiro mês | C4: 46327
B6: Mês | C6: Entradas | D6: Saídas | E6: Lucro | F6: Margem | G6: Lucro acumulado | H6: Nº de entradas
B7: =DATE(YEAR($C$4),MONTH($C$4),1) -> 46327 | C7: =SUMIFS(Lançamentos!$G$5:$G$1004,Lançamentos!$C$5:$C$1004,"Entrada",Lançamentos!$H$5:$H$1004,$B7) -> 600 | D7: =SUMIFS(Lançamentos!$G$5:$G$1004,Lançamentos!$C$5:$C$1004,"Saída",Lançamentos!$H$5:$H$1004,$B7) -> 114 | E7: =C7-D7 -> 486 | F7: =IF(C7>0,E7/C7,0) -> 0.81 | G7: =E7 -> 486 | H7: =COUNTIFS(Lançamentos!$C$5:$C$1004,"Entrada",Lançamentos!$H$5:$H$1004,$B7) -> 1
B8: =DATE(YEAR(B7),MONTH(B7)+1,1) -> 46357 | C8: =SUMIFS(Lançamentos!$G$5:$G$1004,Lançamentos!$C$5:$C$1004,"Entrada",Lançamentos!$H$5:$H$1004,$B8) -> 0 | D8: =SUMIFS(Lançamentos!$G$5:$G$1004,Lançamentos!$C$5:$C$1004,"Saída",Lançamentos!$H$5:$H$1004,$B8) -> 0 | E8: =C8-D8 -> 0 | F8: =IF(C8>0,E8/C8,0) -> 0 | G8: =G7+E8 -> 486 | H8: =COUNTIFS(Lançamentos!$C$5:$C$1004,"Entrada",Lançamentos!$H$5:$H$1004,$B8) -> 0
B9: =DATE(YEAR(B8),MONTH(B8)+1,1) -> 46388 | C9: =SUMIFS(Lançamentos!$G$5:$G$1004,Lançamentos!$C$5:$C$1004,"Entrada",Lançamentos!$H$5:$H$1004,$B9) -> 0 | D9: =SUMIFS(Lançamentos!$G$5:$G$1004,Lançamentos!$C$5:$C$1004,"Saída",Lançamentos!$H$5:$H$1004,$B9) -> 0 | E9: =C9-D9 -> 0 | F9: =IF(C9>0,E9/C9,0) -> 0 | G9: =G8+E9 -> 486 | H9: =COUNTIFS(Lançamentos!$C$5:$C$1004,"Entrada",Lançamentos!$H$5:$H$1004,$B9) -> 0
B10: =DATE(YEAR(B9),MONTH(B9)+1,1) -> 46419 | C10: =SUMIFS(Lançamentos!$G$5:$G$1004,Lançamentos!$C$5:$C$1004,"Entrada",Lançamentos!$H$5:$H$1004,$B10) -> 0 | D10: =SUMIFS(Lançamentos!$G$5:$G$1004,Lançamentos!$C$5:$C$1004,"Saída",Lançamentos!$H$5:$H$1004,$B10) -> 0 | E10: =C10-D10 -> 0 | F10: =IF(C10>0,E10/C10,0) -> 0 | G10: =G9+E10 -> 486 | H10: =COUNTIFS(Lançamentos!$C$5:$C$1004,"Entrada",Lançamentos!$H$5:$H$1004,$B10) -> 0
B11: =DATE(YEAR(B10),MONTH(B10)+1,1) -> 46447 | C11: =SUMIFS(Lançamentos!$G$5:$G$1004,Lançamentos!$C$5:$C$1004,"Entrada",Lançamentos!$H$5:$H$1004,$B11) -> 0 | D11: =SUMIFS(Lançamentos!$G$5:$G$1004,Lançamentos!$C$5:$C$1004,"Saída",Lançamentos!$H$5:$H$1004,$B11) -> 0 | E11: =C11-D11 -> 0 | F11: =IF(C11>0,E11/C11,0) -> 0 | G11: =G10+E11 -> 486 | H11: =COUNTIFS(Lançamentos!$C$5:$C$1004,"Entrada",Lançamentos!$H$5:$H$1004,$B11) -> 0
B12: =DATE(YEAR(B11),MONTH(B11)+1,1) -> 46478 | C12: =SUMIFS(Lançamentos!$G$5:$G$1004,Lançamentos!$C$5:$C$1004,"Entrada",Lançamentos!$H$5:$H$1004,$B12) -> 0 | D12: =SUMIFS(Lançamentos!$G$5:$G$1004,Lançamentos!$C$5:$C$1004,"Saída",Lançamentos!$H$5:$H$1004,$B12) -> 0 | E12: =C12-D12 -> 0 | F12: =IF(C12>0,E12/C12,0) -> 0 | G12: =G11+E12 -> 486 | H12: =COUNTIFS(Lançamentos!$C$5:$C$1004,"Entrada",Lançamentos!$H$5:$H$1004,$B12) -> 0
B13: =DATE(YEAR(B12),MONTH(B12)+1,1) -> 46508 | C13: =SUMIFS(Lançamentos!$G$5:$G$1004,Lançamentos!$C$5:$C$1004,"Entrada",Lançamentos!$H$5:$H$1004,$B13) -> 0 | D13: =SUMIFS(Lançamentos!$G$5:$G$1004,Lançamentos!$C$5:$C$1004,"Saída",Lançamentos!$H$5:$H$1004,$B13) -> 0 | E13: =C13-D13 -> 0 | F13: =IF(C13>0,E13/C13,0) -> 0 | G13: =G12+E13 -> 486 | H13: =COUNTIFS(Lançamentos!$C$5:$C$1004,"Entrada",Lançamentos!$H$5:$H$1004,$B13) -> 0
B14: =DATE(YEAR(B13),MONTH(B13)+1,1) -> 46539 | C14: =SUMIFS(Lançamentos!$G$5:$G$1004,Lançamentos!$C$5:$C$1004,"Entrada",Lançamentos!$H$5:$H$1004,$B14) -> 0 | D14: =SUMIFS(Lançamentos!$G$5:$G$1004,Lançamentos!$C$5:$C$1004,"Saída",Lançamentos!$H$5:$H$1004,$B14) -> 0 | E14: =C14-D14 -> 0 | F14: =IF(C14>0,E14/C14,0) -> 0 | G14: =G13+E14 -> 486 | H14: =COUNTIFS(Lançamentos!$C$5:$C$1004,"Entrada",Lançamentos!$H$5:$H$1004,$B14) -> 0
B15: =DATE(YEAR(B14),MONTH(B14)+1,1) -> 46569 | C15: =SUMIFS(Lançamentos!$G$5:$G$1004,Lançamentos!$C$5:$C$1004,"Entrada",Lançamentos!$H$5:$H$1004,$B15) -> 0 | D15: =SUMIFS(Lançamentos!$G$5:$G$1004,Lançamentos!$C$5:$C$1004,"Saída",Lançamentos!$H$5:$H$1004,$B15) -> 0 | E15: =C15-D15 -> 0 | F15: =IF(C15>0,E15/C15,0) -> 0 | G15: =G14+E15 -> 486 | H15: =COUNTIFS(Lançamentos!$C$5:$C$1004,"Entrada",Lançamentos!$H$5:$H$1004,$B15) -> 0
B16: =DATE(YEAR(B15),MONTH(B15)+1,1) -> 46600 | C16: =SUMIFS(Lançamentos!$G$5:$G$1004,Lançamentos!$C$5:$C$1004,"Entrada",Lançamentos!$H$5:$H$1004,$B16) -> 0 | D16: =SUMIFS(Lançamentos!$G$5:$G$1004,Lançamentos!$C$5:$C$1004,"Saída",Lançamentos!$H$5:$H$1004,$B16) -> 0 | E16: =C16-D16 -> 0 | F16: =IF(C16>0,E16/C16,0) -> 0 | G16: =G15+E16 -> 486 | H16: =COUNTIFS(Lançamentos!$C$5:$C$1004,"Entrada",Lançamentos!$H$5:$H$1004,$B16) -> 0
B17: =DATE(YEAR(B16),MONTH(B16)+1,1) -> 46631 | C17: =SUMIFS(Lançamentos!$G$5:$G$1004,Lançamentos!$C$5:$C$1004,"Entrada",Lançamentos!$H$5:$H$1004,$B17) -> 0 | D17: =SUMIFS(Lançamentos!$G$5:$G$1004,Lançamentos!$C$5:$C$1004,"Saída",Lançamentos!$H$5:$H$1004,$B17) -> 0 | E17: =C17-D17 -> 0 | F17: =IF(C17>0,E17/C17,0) -> 0 | G17: =G16+E17 -> 486 | H17: =COUNTIFS(Lançamentos!$C$5:$C$1004,"Entrada",Lançamentos!$H$5:$H$1004,$B17) -> 0
B18: =DATE(YEAR(B17),MONTH(B17)+1,1) -> 46661 | C18: =SUMIFS(Lançamentos!$G$5:$G$1004,Lançamentos!$C$5:$C$1004,"Entrada",Lançamentos!$H$5:$H$1004,$B18) -> 0 | D18: =SUMIFS(Lançamentos!$G$5:$G$1004,Lançamentos!$C$5:$C$1004,"Saída",Lançamentos!$H$5:$H$1004,$B18) -> 0 | E18: =C18-D18 -> 0 | F18: =IF(C18>0,E18/C18,0) -> 0 | G18: =G17+E18 -> 486 | H18: =COUNTIFS(Lançamentos!$C$5:$C$1004,"Entrada",Lançamentos!$H$5:$H$1004,$B18) -> 0
B19: Total dos 12 meses | C19: =SUM(C7:C18) -> 600 | D19: =SUM(D7:D18) -> 114 | E19: =C19-D19 -> 486 | F19: =IF(C19>0,E19/C19,0) -> 0.81 | H19: =SUM(H7:H18) -> 1
B22: Entradas por categoria
B23: Categoria | C23: =$B$7 -> 46327 | D23: =$B$8 -> 46357 | E23: =$B$9 -> 46388 | F23: =$B$10 -> 46419 | G23: =$B$11 -> 46447 | H23: =$B$12 -> 46478 | I23: =$B$13 -> 46508 | J23: =$B$14 -> 46539 | K23: =$B$15 -> 46569 | L23: =$B$16 -> 46600 | M23: =$B$17 -> 46631 | N23: =$B$18 -> 46661 | O23: Total
B24: =IFERROR(INDEX(Listas!$B$5:$B$40,MATCH(ROWS($B$24:B24),Listas!$D$5:$D$40,0)),"") -> Site WhatsApp | C24: =IF($B24="","",SUMIFS(Lançamentos!$G$5:$G$1004,Lançamentos!$B$5:$B$1004,$B24,Lançamentos!$H$5:$H$1004,C$23)) -> 600 | D24: =IF($B24="","",SUMIFS(Lançamentos!$G$5:$G$1004,Lançamentos!$B$5:$B$1004,$B24,Lançamentos!$H$5:$H$1004,D$23)) -> 0 | E24: =IF($B24="","",SUMIFS(Lançamentos!$G$5:$G$1004,Lançamentos!$B$5:$B$1004,$B24,Lançamentos!$H$5:$H$1004,E$23)) -> 0 | F24: =IF($B24="","",SUMIFS(Lançamentos!$G$5:$G$1004,Lançamentos!$B$5:$B$1004,$B24,Lançamentos!$H$5:$H$1004,F$23)) -> 0 | G24: =IF($B24="","",SUMIFS(Lançamentos!$G$5:$G$1004,Lançamentos!$B$5:$B$1004,$B24,Lançamentos!$H$5:$H$1004,G$23)) -> 0 | H24: =IF($B24="","",SUMIFS(Lançamentos!$G$5:$G$1004,Lançamentos!$B$5:$B$1004,$B24,Lançamentos!$H$5:$H$1004,H$23)) -> 0 | I24: =IF($B24="","",SUMIFS(Lançamentos!$G$5:$G$1004,Lançamentos!$B$5:$B$1004,$B24,Lançamentos!$H$5:$H$1004,I$23)) -> 0 | J24: =IF($B24="","",SUMIFS(Lançamentos!$G$5:$G$1004,Lançamentos!$B$5:$B$1004,$B24,Lançamentos!$H$5:$H$1004,J$23)) -> 0 | ... N24: =IF($B24="","",SUMIFS(Lançamentos!$G$5:$G$1004,Lançamentos!$B$5:$B$1004,$B24,Lançamentos!$H$5:$H$1004,N$23)) -> 0 | O24: =IF($B24="","",SUM(C24:N24)) -> 600
B25: =IFERROR(INDEX(Listas!$B$5:$B$40,MATCH(ROWS($B$24:B25),Listas!$D$5:$D$40,0)),"") -> Loja virtual | C25: =IF($B25="","",SUMIFS(Lançamentos!$G$5:$G$1004,Lançamentos!$B$5:$B$1004,$B25,Lançamentos!$H$5:$H$1004,C$23)) -> 0 | D25: =IF($B25="","",SUMIFS(Lançamentos!$G$5:$G$1004,Lançamentos!$B$5:$B$1004,$B25,Lançamentos!$H$5:$H$1004,D$23)) -> 0 | E25: =IF($B25="","",SUMIFS(Lançamentos!$G$5:$G$1004,Lançamentos!$B$5:$B$1004,$B25,Lançamentos!$H$5:$H$1004,E$23)) -> 0 | F25: =IF($B25="","",SUMIFS(Lançamentos!$G$5:$G$1004,Lançamentos!$B$5:$B$1004,$B25,Lançamentos!$H$5:$H$1004,F$23)) -> 0 | G25: =IF($B25="","",SUMIFS(Lançamentos!$G$5:$G$1004,Lançamentos!$B$5:$B$1004,$B25,Lançamentos!$H$5:$H$1004,G$23)) -> 0 | H25: =IF($B25="","",SUMIFS(Lançamentos!$G$5:$G$1004,Lançamentos!$B$5:$B$1004,$B25,Lançamentos!$H$5:$H$1004,H$23)) -> 0 | I25: =IF($B25="","",SUMIFS(Lançamentos!$G$5:$G$1004,Lançamentos!$B$5:$B$1004,$B25,Lançamentos!$H$5:$H$1004,I$23)) -> 0 | J25: =IF($B25="","",SUMIFS(Lançamentos!$G$5:$G$1004,Lançamentos!$B$5:$B$1004,$B25,Lançamentos!$H$5:$H$1004,J$23)) -> 0 | ... N25: =IF($B25="","",SUMIFS(Lançamentos!$G$5:$G$1004,Lançamentos!$B$5:$B$1004,$B25,Lançamentos!$H$5:$H$1004,N$23)) -> 0 | O25: =IF($B25="","",SUM(C25:N25)) -> 0
B26: =IFERROR(INDEX(Listas!$B$5:$B$40,MATCH(ROWS($B$24:B26),Listas!$D$5:$D$40,0)),"") -> SaaS / sistema | C26: =IF($B26="","",SUMIFS(Lançamentos!$G$5:$G$1004,Lançamentos!$B$5:$B$1004,$B26,Lançamentos!$H$5:$H$1004,C$23)) -> 0 | D26: =IF($B26="","",SUMIFS(Lançamentos!$G$5:$G$1004,Lançamentos!$B$5:$B$1004,$B26,Lançamentos!$H$5:$H$1004,D$23)) -> 0 | E26: =IF($B26="","",SUMIFS(Lançamentos!$G$5:$G$1004,Lançamentos!$B$5:$B$1004,$B26,Lançamentos!$H$5:$H$1004,E$23)) -> 0 | F26: =IF($B26="","",SUMIFS(Lançamentos!$G$5:$G$1004,Lançamentos!$B$5:$B$1004,$B26,Lançamentos!$H$5:$H$1004,F$23)) -> 0 | G26: =IF($B26="","",SUMIFS(Lançamentos!$G$5:$G$1004,Lançamentos!$B$5:$B$1004,$B26,Lançamentos!$H$5:$H$1004,G$23)) -> 0 | H26: =IF($B26="","",SUMIFS(Lançamentos!$G$5:$G$1004,Lançamentos!$B$5:$B$1004,$B26,Lançamentos!$H$5:$H$1004,H$23)) -> 0 | I26: =IF($B26="","",SUMIFS(Lançamentos!$G$5:$G$1004,Lançamentos!$B$5:$B$1004,$B26,Lançamentos!$H$5:$H$1004,I$23)) -> 0 | J26: =IF($B26="","",SUMIFS(Lançamentos!$G$5:$G$1004,Lançamentos!$B$5:$B$1004,$B26,Lançamentos!$H$5:$H$1004,J$23)) -> 0 | ... N26: =IF($B26="","",SUMIFS(Lançamentos!$G$5:$G$1004,Lançamentos!$B$5:$B$1004,$B26,Lançamentos!$H$5:$H$1004,N$23)) -> 0 | O26: =IF($B26="","",SUM(C26:N26)) -> 0
B27: =IFERROR(INDEX(Listas!$B$5:$B$40,MATCH(ROWS($B$24:B27),Listas!$D$5:$D$40,0)),"") -> Mensalidade de cliente | C27: =IF($B27="","",SUMIFS(Lançamentos!$G$5:$G$1004,Lançamentos!$B$5:$B$1004,$B27,Lançamentos!$H$5:$H$1004,C$23)) -> 0 | D27: =IF($B27="","",SUMIFS(Lançamentos!$G$5:$G$1004,Lançamentos!$B$5:$B$1004,$B27,Lançamentos!$H$5:$H$1004,D$23)) -> 0 | E27: =IF($B27="","",SUMIFS(Lançamentos!$G$5:$G$1004,Lançamentos!$B$5:$B$1004,$B27,Lançamentos!$H$5:$H$1004,E$23)) -> 0 | F27: =IF($B27="","",SUMIFS(Lançamentos!$G$5:$G$1004,Lançamentos!$B$5:$B$1004,$B27,Lançamentos!$H$5:$H$1004,F$23)) -> 0 | G27: =IF($B27="","",SUMIFS(Lançamentos!$G$5:$G$1004,Lançamentos!$B$5:$B$1004,$B27,Lançamentos!$H$5:$H$1004,G$23)) -> 0 | H27: =IF($B27="","",SUMIFS(Lançamentos!$G$5:$G$1004,Lançamentos!$B$5:$B$1004,$B27,Lançamentos!$H$5:$H$1004,H$23)) -> 0 | I27: =IF($B27="","",SUMIFS(Lançamentos!$G$5:$G$1004,Lançamentos!$B$5:$B$1004,$B27,Lançamentos!$H$5:$H$1004,I$23)) -> 0 | J27: =IF($B27="","",SUMIFS(Lançamentos!$G$5:$G$1004,Lançamentos!$B$5:$B$1004,$B27,Lançamentos!$H$5:$H$1004,J$23)) -> 0 | ... N27: =IF($B27="","",SUMIFS(Lançamentos!$G$5:$G$1004,Lançamentos!$B$5:$B$1004,$B27,Lançamentos!$H$5:$H$1004,N$23)) -> 0 | O27: =IF($B27="","",SUM(C27:N27)) -> 0
B28: =IFERROR(INDEX(Listas!$B$5:$B$40,MATCH(ROWS($B$24:B28),Listas!$D$5:$D$40,0)),"") -> Extras e ajustes | C28: =IF($B28="","",SUMIFS(Lançamentos!$G$5:$G$1004,Lançamentos!$B$5:$B$1004,$B28,Lançamentos!$H$5:$H$1004,C$23)) -> 0 | D28: =IF($B28="","",SUMIFS(Lançamentos!$G$5:$G$1004,Lançamentos!$B$5:$B$1004,$B28,Lançamentos!$H$5:$H$1004,D$23)) -> 0 | E28: =IF($B28="","",SUMIFS(Lançamentos!$G$5:$G$1004,Lançamentos!$B$5:$B$1004,$B28,Lançamentos!$H$5:$H$1004,E$23)) -> 0 | F28: =IF($B28="","",SUMIFS(Lançamentos!$G$5:$G$1004,Lançamentos!$B$5:$B$1004,$B28,Lançamentos!$H$5:$H$1004,F$23)) -> 0 | G28: =IF($B28="","",SUMIFS(Lançamentos!$G$5:$G$1004,Lançamentos!$B$5:$B$1004,$B28,Lançamentos!$H$5:$H$1004,G$23)) -> 0 | H28: =IF($B28="","",SUMIFS(Lançamentos!$G$5:$G$1004,Lançamentos!$B$5:$B$1004,$B28,Lançamentos!$H$5:$H$1004,H$23)) -> 0 | I28: =IF($B28="","",SUMIFS(Lançamentos!$G$5:$G$1004,Lançamentos!$B$5:$B$1004,$B28,Lançamentos!$H$5:$H$1004,I$23)) -> 0 | J28: =IF($B28="","",SUMIFS(Lançamentos!$G$5:$G$1004,Lançamentos!$B$5:$B$1004,$B28,Lançamentos!$H$5:$H$1004,J$23)) -> 0 | ... N28: =IF($B28="","",SUMIFS(Lançamentos!$G$5:$G$1004,Lançamentos!$B$5:$B$1004,$B28,Lançamentos!$H$5:$H$1004,N$23)) -> 0 | O28: =IF($B28="","",SUM(C28:N28)) -> 0
B29: =IFERROR(INDEX(Listas!$B$5:$B$40,MATCH(ROWS($B$24:B29),Listas!$D$5:$D$40,0)),"") -> Repasse de domínio | C29: =IF($B29="","",SUMIFS(Lançamentos!$G$5:$G$1004,Lançamentos!$B$5:$B$1004,$B29,Lançamentos!$H$5:$H$1004,C$23)) -> 0 | D29: =IF($B29="","",SUMIFS(Lançamentos!$G$5:$G$1004,Lançamentos!$B$5:$B$1004,$B29,Lançamentos!$H$5:$H$1004,D$23)) -> 0 | E29: =IF($B29="","",SUMIFS(Lançamentos!$G$5:$G$1004,Lançamentos!$B$5:$B$1004,$B29,Lançamentos!$H$5:$H$1004,E$23)) -> 0 | F29: =IF($B29="","",SUMIFS(Lançamentos!$G$5:$G$1004,Lançamentos!$B$5:$B$1004,$B29,Lançamentos!$H$5:$H$1004,F$23)) -> 0 | G29: =IF($B29="","",SUMIFS(Lançamentos!$G$5:$G$1004,Lançamentos!$B$5:$B$1004,$B29,Lançamentos!$H$5:$H$1004,G$23)) -> 0 | H29: =IF($B29="","",SUMIFS(Lançamentos!$G$5:$G$1004,Lançamentos!$B$5:$B$1004,$B29,Lançamentos!$H$5:$H$1004,H$23)) -> 0 | I29: =IF($B29="","",SUMIFS(Lançamentos!$G$5:$G$1004,Lançamentos!$B$5:$B$1004,$B29,Lançamentos!$H$5:$H$1004,I$23)) -> 0 | J29: =IF($B29="","",SUMIFS(Lançamentos!$G$5:$G$1004,Lançamentos!$B$5:$B$1004,$B29,Lançamentos!$H$5:$H$1004,J$23)) -> 0 | ... N29: =IF($B29="","",SUMIFS(Lançamentos!$G$5:$G$1004,Lançamentos!$B$5:$B$1004,$B29,Lançamentos!$H$5:$H$1004,N$23)) -> 0 | O29: =IF($B29="","",SUM(C29:N29)) -> 0
B30: =IFERROR(INDEX(Listas!$B$5:$B$40,MATCH(ROWS($B$24:B30),Listas!$D$5:$D$40,0)),"") -> Outras entradas | C30: =IF($B30="","",SUMIFS(Lançamentos!$G$5:$G$1004,Lançamentos!$B$5:$B$1004,$B30,Lançamentos!$H$5:$H$1004,C$23)) -> 0 | D30: =IF($B30="","",SUMIFS(Lançamentos!$G$5:$G$1004,Lançamentos!$B$5:$B$1004,$B30,Lançamentos!$H$5:$H$1004,D$23)) -> 0 | E30: =IF($B30="","",SUMIFS(Lançamentos!$G$5:$G$1004,Lançamentos!$B$5:$B$1004,$B30,Lançamentos!$H$5:$H$1004,E$23)) -> 0 | F30: =IF($B30="","",SUMIFS(Lançamentos!$G$5:$G$1004,Lançamentos!$B$5:$B$1004,$B30,Lançamentos!$H$5:$H$1004,F$23)) -> 0 | G30: =IF($B30="","",SUMIFS(Lançamentos!$G$5:$G$1004,Lançamentos!$B$5:$B$1004,$B30,Lançamentos!$H$5:$H$1004,G$23)) -> 0 | H30: =IF($B30="","",SUMIFS(Lançamentos!$G$5:$G$1004,Lançamentos!$B$5:$B$1004,$B30,Lançamentos!$H$5:$H$1004,H$23)) -> 0 | I30: =IF($B30="","",SUMIFS(Lançamentos!$G$5:$G$1004,Lançamentos!$B$5:$B$1004,$B30,Lançamentos!$H$5:$H$1004,I$23)) -> 0 | J30: =IF($B30="","",SUMIFS(Lançamentos!$G$5:$G$1004,Lançamentos!$B$5:$B$1004,$B30,Lançamentos!$H$5:$H$1004,J$23)) -> 0 | ... N30: =IF($B30="","",SUMIFS(Lançamentos!$G$5:$G$1004,Lançamentos!$B$5:$B$1004,$B30,Lançamentos!$H$5:$H$1004,N$23)) -> 0 | O30: =IF($B30="","",SUM(C30:N30)) -> 0
B31: =IFERROR(INDEX(Listas!$B$5:$B$40,MATCH(ROWS($B$24:B31),Listas!$D$5:$D$40,0)),"") | C31: =IF($B31="","",SUMIFS(Lançamentos!$G$5:$G$1004,Lançamentos!$B$5:$B$1004,$B31,Lançamentos!$H$5:$H$1004,C$23)) | D31: =IF($B31="","",SUMIFS(Lançamentos!$G$5:$G$1004,Lançamentos!$B$5:$B$1004,$B31,Lançamentos!$H$5:$H$1004,D$23)) | E31: =IF($B31="","",SUMIFS(Lançamentos!$G$5:$G$1004,Lançamentos!$B$5:$B$1004,$B31,Lançamentos!$H$5:$H$1004,E$23)) | F31: =IF($B31="","",SUMIFS(Lançamentos!$G$5:$G$1004,Lançamentos!$B$5:$B$1004,$B31,Lançamentos!$H$5:$H$1004,F$23)) | G31: =IF($B31="","",SUMIFS(Lançamentos!$G$5:$G$1004,Lançamentos!$B$5:$B$1004,$B31,Lançamentos!$H$5:$H$1004,G$23)) | H31: =IF($B31="","",SUMIFS(Lançamentos!$G$5:$G$1004,Lançamentos!$B$5:$B$1004,$B31,Lançamentos!$H$5:$H$1004,H$23)) | I31: =IF($B31="","",SUMIFS(Lançamentos!$G$5:$G$1004,Lançamentos!$B$5:$B$1004,$B31,Lançamentos!$H$5:$H$1004,I$23)) | J31: =IF($B31="","",SUMIFS(Lançamentos!$G$5:$G$1004,Lançamentos!$B$5:$B$1004,$B31,Lançamentos!$H$5:$H$1004,J$23)) | ... N31: =IF($B31="","",SUMIFS(Lançamentos!$G$5:$G$1004,Lançamentos!$B$5:$B$1004,$B31,Lançamentos!$H$5:$H$1004,N$23)) | O31: =IF($B31="","",SUM(C31:N31))
B32: =IFERROR(INDEX(Listas!$B$5:$B$40,MATCH(ROWS($B$24:B32),Listas!$D$5:$D$40,0)),"") | C32: =IF($B32="","",SUMIFS(Lançamentos!$G$5:$G$1004,Lançamentos!$B$5:$B$1004,$B32,Lançamentos!$H$5:$H$1004,C$23)) | D32: =IF($B32="","",SUMIFS(Lançamentos!$G$5:$G$1004,Lançamentos!$B$5:$B$1004,$B32,Lançamentos!$H$5:$H$1004,D$23)) | E32: =IF($B32="","",SUMIFS(Lançamentos!$G$5:$G$1004,Lançamentos!$B$5:$B$1004,$B32,Lançamentos!$H$5:$H$1004,E$23)) | F32: =IF($B32="","",SUMIFS(Lançamentos!$G$5:$G$1004,Lançamentos!$B$5:$B$1004,$B32,Lançamentos!$H$5:$H$1004,F$23)) | G32: =IF($B32="","",SUMIFS(Lançamentos!$G$5:$G$1004,Lançamentos!$B$5:$B$1004,$B32,Lançamentos!$H$5:$H$1004,G$23)) | H32: =IF($B32="","",SUMIFS(Lançamentos!$G$5:$G$1004,Lançamentos!$B$5:$B$1004,$B32,Lançamentos!$H$5:$H$1004,H$23)) | I32: =IF($B32="","",SUMIFS(Lançamentos!$G$5:$G$1004,Lançamentos!$B$5:$B$1004,$B32,Lançamentos!$H$5:$H$1004,I$23)) | J32: =IF($B32="","",SUMIFS(Lançamentos!$G$5:$G$1004,Lançamentos!$B$5:$B$1004,$B32,Lançamentos!$H$5:$H$1004,J$23)) | ... N32: =IF($B32="","",SUMIFS(Lançamentos!$G$5:$G$1004,Lançamentos!$B$5:$B$1004,$B32,Lançamentos!$H$5:$H$1004,N$23)) | O32: =IF($B32="","",SUM(C32:N32))
B33: =IFERROR(INDEX(Listas!$B$5:$B$40,MATCH(ROWS($B$24:B33),Listas!$D$5:$D$40,0)),"") | C33: =IF($B33="","",SUMIFS(Lançamentos!$G$5:$G$1004,Lançamentos!$B$5:$B$1004,$B33,Lançamentos!$H$5:$H$1004,C$23)) | D33: =IF($B33="","",SUMIFS(Lançamentos!$G$5:$G$1004,Lançamentos!$B$5:$B$1004,$B33,Lançamentos!$H$5:$H$1004,D$23)) | E33: =IF($B33="","",SUMIFS(Lançamentos!$G$5:$G$1004,Lançamentos!$B$5:$B$1004,$B33,Lançamentos!$H$5:$H$1004,E$23)) | F33: =IF($B33="","",SUMIFS(Lançamentos!$G$5:$G$1004,Lançamentos!$B$5:$B$1004,$B33,Lançamentos!$H$5:$H$1004,F$23)) | G33: =IF($B33="","",SUMIFS(Lançamentos!$G$5:$G$1004,Lançamentos!$B$5:$B$1004,$B33,Lançamentos!$H$5:$H$1004,G$23)) | H33: =IF($B33="","",SUMIFS(Lançamentos!$G$5:$G$1004,Lançamentos!$B$5:$B$1004,$B33,Lançamentos!$H$5:$H$1004,H$23)) | I33: =IF($B33="","",SUMIFS(Lançamentos!$G$5:$G$1004,Lançamentos!$B$5:$B$1004,$B33,Lançamentos!$H$5:$H$1004,I$23)) | J33: =IF($B33="","",SUMIFS(Lançamentos!$G$5:$G$1004,Lançamentos!$B$5:$B$1004,$B33,Lançamentos!$H$5:$H$1004,J$23)) | ... N33: =IF($B33="","",SUMIFS(Lançamentos!$G$5:$G$1004,Lançamentos!$B$5:$B$1004,$B33,Lançamentos!$H$5:$H$1004,N$23)) | O33: =IF($B33="","",SUM(C33:N33))
B34: Total de entradas | C34: =SUM(C24:C33) -> 600 | D34: =SUM(D24:D33) -> 0 | E34: =SUM(E24:E33) -> 0 | F34: =SUM(F24:F33) -> 0 | G34: =SUM(G24:G33) -> 0 | H34: =SUM(H24:H33) -> 0 | I34: =SUM(I24:I33) -> 0 | J34: =SUM(J24:J33) -> 0 | ... O34: =SUM(O24:O33) -> 600
B37: Saídas por categoria
B38: Categoria | C38: =$B$7 -> 46327 | D38: =$B$8 -> 46357 | E38: =$B$9 -> 46388 | F38: =$B$10 -> 46419 | G38: =$B$11 -> 46447 | H38: =$B$12 -> 46478 | I38: =$B$13 -> 46508 | J38: =$B$14 -> 46539 | K38: =$B$15 -> 46569 | L38: =$B$16 -> 46600 | M38: =$B$17 -> 46631 | N38: =$B$18 -> 46661 | O38: Total
B39: =IFERROR(INDEX(Listas!$B$5:$B$40,MATCH(ROWS($B$39:B39),Listas!$E$5:$E$40,0)),"") -> Inteligência artificial | C39: =IF($B39="","",SUMIFS(Lançamentos!$G$5:$G$1004,Lançamentos!$B$5:$B$1004,$B39,Lançamentos!$H$5:$H$1004,C$38)) -> 114 | D39: =IF($B39="","",SUMIFS(Lançamentos!$G$5:$G$1004,Lançamentos!$B$5:$B$1004,$B39,Lançamentos!$H$5:$H$1004,D$38)) -> 0 | E39: =IF($B39="","",SUMIFS(Lançamentos!$G$5:$G$1004,Lançamentos!$B$5:$B$1004,$B39,Lançamentos!$H$5:$H$1004,E$38)) -> 0 | F39: =IF($B39="","",SUMIFS(Lançamentos!$G$5:$G$1004,Lançamentos!$B$5:$B$1004,$B39,Lançamentos!$H$5:$H$1004,F$38)) -> 0 | G39: =IF($B39="","",SUMIFS(Lançamentos!$G$5:$G$1004,Lançamentos!$B$5:$B$1004,$B39,Lançamentos!$H$5:$H$1004,G$38)) -> 0 | H39: =IF($B39="","",SUMIFS(Lançamentos!$G$5:$G$1004,Lançamentos!$B$5:$B$1004,$B39,Lançamentos!$H$5:$H$1004,H$38)) -> 0 | I39: =IF($B39="","",SUMIFS(Lançamentos!$G$5:$G$1004,Lançamentos!$B$5:$B$1004,$B39,Lançamentos!$H$5:$H$1004,I$38)) -> 0 | J39: =IF($B39="","",SUMIFS(Lançamentos!$G$5:$G$1004,Lançamentos!$B$5:$B$1004,$B39,Lançamentos!$H$5:$H$1004,J$38)) -> 0 | ... N39: =IF($B39="","",SUMIFS(Lançamentos!$G$5:$G$1004,Lançamentos!$B$5:$B$1004,$B39,Lançamentos!$H$5:$H$1004,N$38)) -> 0 | O39: =IF($B39="","",SUM(C39:N39)) -> 114
B40: =IFERROR(INDEX(Listas!$B$5:$B$40,MATCH(ROWS($B$39:B40),Listas!$E$5:$E$40,0)),"") -> Domínios | C40: =IF($B40="","",SUMIFS(Lançamentos!$G$5:$G$1004,Lançamentos!$B$5:$B$1004,$B40,Lançamentos!$H$5:$H$1004,C$38)) -> 0 | D40: =IF($B40="","",SUMIFS(Lançamentos!$G$5:$G$1004,Lançamentos!$B$5:$B$1004,$B40,Lançamentos!$H$5:$H$1004,D$38)) -> 0 | E40: =IF($B40="","",SUMIFS(Lançamentos!$G$5:$G$1004,Lançamentos!$B$5:$B$1004,$B40,Lançamentos!$H$5:$H$1004,E$38)) -> 0 | F40: =IF($B40="","",SUMIFS(Lançamentos!$G$5:$G$1004,Lançamentos!$B$5:$B$1004,$B40,Lançamentos!$H$5:$H$1004,F$38)) -> 0 | G40: =IF($B40="","",SUMIFS(Lançamentos!$G$5:$G$1004,Lançamentos!$B$5:$B$1004,$B40,Lançamentos!$H$5:$H$1004,G$38)) -> 0 | H40: =IF($B40="","",SUMIFS(Lançamentos!$G$5:$G$1004,Lançamentos!$B$5:$B$1004,$B40,Lançamentos!$H$5:$H$1004,H$38)) -> 0 | I40: =IF($B40="","",SUMIFS(Lançamentos!$G$5:$G$1004,Lançamentos!$B$5:$B$1004,$B40,Lançamentos!$H$5:$H$1004,I$38)) -> 0 | J40: =IF($B40="","",SUMIFS(Lançamentos!$G$5:$G$1004,Lançamentos!$B$5:$B$1004,$B40,Lançamentos!$H$5:$H$1004,J$38)) -> 0 | ... N40: =IF($B40="","",SUMIFS(Lançamentos!$G$5:$G$1004,Lançamentos!$B$5:$B$1004,$B40,Lançamentos!$H$5:$H$1004,N$38)) -> 0 | O40: =IF($B40="","",SUM(C40:N40)) -> 0
B41: =IFERROR(INDEX(Listas!$B$5:$B$40,MATCH(ROWS($B$39:B41),Listas!$E$5:$E$40,0)),"") -> Hospedagem | C41: =IF($B41="","",SUMIFS(Lançamentos!$G$5:$G$1004,Lançamentos!$B$5:$B$1004,$B41,Lançamentos!$H$5:$H$1004,C$38)) -> 0 | D41: =IF($B41="","",SUMIFS(Lançamentos!$G$5:$G$1004,Lançamentos!$B$5:$B$1004,$B41,Lançamentos!$H$5:$H$1004,D$38)) -> 0 | E41: =IF($B41="","",SUMIFS(Lançamentos!$G$5:$G$1004,Lançamentos!$B$5:$B$1004,$B41,Lançamentos!$H$5:$H$1004,E$38)) -> 0 | F41: =IF($B41="","",SUMIFS(Lançamentos!$G$5:$G$1004,Lançamentos!$B$5:$B$1004,$B41,Lançamentos!$H$5:$H$1004,F$38)) -> 0 | G41: =IF($B41="","",SUMIFS(Lançamentos!$G$5:$G$1004,Lançamentos!$B$5:$B$1004,$B41,Lançamentos!$H$5:$H$1004,G$38)) -> 0 | H41: =IF($B41="","",SUMIFS(Lançamentos!$G$5:$G$1004,Lançamentos!$B$5:$B$1004,$B41,Lançamentos!$H$5:$H$1004,H$38)) -> 0 | I41: =IF($B41="","",SUMIFS(Lançamentos!$G$5:$G$1004,Lançamentos!$B$5:$B$1004,$B41,Lançamentos!$H$5:$H$1004,I$38)) -> 0 | J41: =IF($B41="","",SUMIFS(Lançamentos!$G$5:$G$1004,Lançamentos!$B$5:$B$1004,$B41,Lançamentos!$H$5:$H$1004,J$38)) -> 0 | ... N41: =IF($B41="","",SUMIFS(Lançamentos!$G$5:$G$1004,Lançamentos!$B$5:$B$1004,$B41,Lançamentos!$H$5:$H$1004,N$38)) -> 0 | O41: =IF($B41="","",SUM(C41:N41)) -> 0
B42: =IFERROR(INDEX(Listas!$B$5:$B$40,MATCH(ROWS($B$39:B42),Listas!$E$5:$E$40,0)),"") -> Shopify e plataformas | C42: =IF($B42="","",SUMIFS(Lançamentos!$G$5:$G$1004,Lançamentos!$B$5:$B$1004,$B42,Lançamentos!$H$5:$H$1004,C$38)) -> 0 | D42: =IF($B42="","",SUMIFS(Lançamentos!$G$5:$G$1004,Lançamentos!$B$5:$B$1004,$B42,Lançamentos!$H$5:$H$1004,D$38)) -> 0 | E42: =IF($B42="","",SUMIFS(Lançamentos!$G$5:$G$1004,Lançamentos!$B$5:$B$1004,$B42,Lançamentos!$H$5:$H$1004,E$38)) -> 0 | F42: =IF($B42="","",SUMIFS(Lançamentos!$G$5:$G$1004,Lançamentos!$B$5:$B$1004,$B42,Lançamentos!$H$5:$H$1004,F$38)) -> 0 | G42: =IF($B42="","",SUMIFS(Lançamentos!$G$5:$G$1004,Lançamentos!$B$5:$B$1004,$B42,Lançamentos!$H$5:$H$1004,G$38)) -> 0 | H42: =IF($B42="","",SUMIFS(Lançamentos!$G$5:$G$1004,Lançamentos!$B$5:$B$1004,$B42,Lançamentos!$H$5:$H$1004,H$38)) -> 0 | I42: =IF($B42="","",SUMIFS(Lançamentos!$G$5:$G$1004,Lançamentos!$B$5:$B$1004,$B42,Lançamentos!$H$5:$H$1004,I$38)) -> 0 | J42: =IF($B42="","",SUMIFS(Lançamentos!$G$5:$G$1004,Lançamentos!$B$5:$B$1004,$B42,Lançamentos!$H$5:$H$1004,J$38)) -> 0 | ... N42: =IF($B42="","",SUMIFS(Lançamentos!$G$5:$G$1004,Lançamentos!$B$5:$B$1004,$B42,Lançamentos!$H$5:$H$1004,N$38)) -> 0 | O42: =IF($B42="","",SUM(C42:N42)) -> 0
B43: =IFERROR(INDEX(Listas!$B$5:$B$40,MATCH(ROWS($B$39:B43),Listas!$E$5:$E$40,0)),"") -> Ferramentas e apps | C43: =IF($B43="","",SUMIFS(Lançamentos!$G$5:$G$1004,Lançamentos!$B$5:$B$1004,$B43,Lançamentos!$H$5:$H$1004,C$38)) -> 0 | D43: =IF($B43="","",SUMIFS(Lançamentos!$G$5:$G$1004,Lançamentos!$B$5:$B$1004,$B43,Lançamentos!$H$5:$H$1004,D$38)) -> 0 | E43: =IF($B43="","",SUMIFS(Lançamentos!$G$5:$G$1004,Lançamentos!$B$5:$B$1004,$B43,Lançamentos!$H$5:$H$1004,E$38)) -> 0 | F43: =IF($B43="","",SUMIFS(Lançamentos!$G$5:$G$1004,Lançamentos!$B$5:$B$1004,$B43,Lançamentos!$H$5:$H$1004,F$38)) -> 0 | G43: =IF($B43="","",SUMIFS(Lançamentos!$G$5:$G$1004,Lançamentos!$B$5:$B$1004,$B43,Lançamentos!$H$5:$H$1004,G$38)) -> 0 | H43: =IF($B43="","",SUMIFS(Lançamentos!$G$5:$G$1004,Lançamentos!$B$5:$B$1004,$B43,Lançamentos!$H$5:$H$1004,H$38)) -> 0 | I43: =IF($B43="","",SUMIFS(Lançamentos!$G$5:$G$1004,Lançamentos!$B$5:$B$1004,$B43,Lançamentos!$H$5:$H$1004,I$38)) -> 0 | J43: =IF($B43="","",SUMIFS(Lançamentos!$G$5:$G$1004,Lançamentos!$B$5:$B$1004,$B43,Lançamentos!$H$5:$H$1004,J$38)) -> 0 | ... N43: =IF($B43="","",SUMIFS(Lançamentos!$G$5:$G$1004,Lançamentos!$B$5:$B$1004,$B43,Lançamentos!$H$5:$H$1004,N$38)) -> 0 | O43: =IF($B43="","",SUM(C43:N43)) -> 0
B44: =IFERROR(INDEX(Listas!$B$5:$B$40,MATCH(ROWS($B$39:B44),Listas!$E$5:$E$40,0)),"") -> Anúncios e marketing | C44: =IF($B44="","",SUMIFS(Lançamentos!$G$5:$G$1004,Lançamentos!$B$5:$B$1004,$B44,Lançamentos!$H$5:$H$1004,C$38)) -> 0 | D44: =IF($B44="","",SUMIFS(Lançamentos!$G$5:$G$1004,Lançamentos!$B$5:$B$1004,$B44,Lançamentos!$H$5:$H$1004,D$38)) -> 0 | E44: =IF($B44="","",SUMIFS(Lançamentos!$G$5:$G$1004,Lançamentos!$B$5:$B$1004,$B44,Lançamentos!$H$5:$H$1004,E$38)) -> 0 | F44: =IF($B44="","",SUMIFS(Lançamentos!$G$5:$G$1004,Lançamentos!$B$5:$B$1004,$B44,Lançamentos!$H$5:$H$1004,F$38)) -> 0 | G44: =IF($B44="","",SUMIFS(Lançamentos!$G$5:$G$1004,Lançamentos!$B$5:$B$1004,$B44,Lançamentos!$H$5:$H$1004,G$38)) -> 0 | H44: =IF($B44="","",SUMIFS(Lançamentos!$G$5:$G$1004,Lançamentos!$B$5:$B$1004,$B44,Lançamentos!$H$5:$H$1004,H$38)) -> 0 | I44: =IF($B44="","",SUMIFS(Lançamentos!$G$5:$G$1004,Lançamentos!$B$5:$B$1004,$B44,Lançamentos!$H$5:$H$1004,I$38)) -> 0 | J44: =IF($B44="","",SUMIFS(Lançamentos!$G$5:$G$1004,Lançamentos!$B$5:$B$1004,$B44,Lançamentos!$H$5:$H$1004,J$38)) -> 0 | ... N44: =IF($B44="","",SUMIFS(Lançamentos!$G$5:$G$1004,Lançamentos!$B$5:$B$1004,$B44,Lançamentos!$H$5:$H$1004,N$38)) -> 0 | O44: =IF($B44="","",SUM(C44:N44)) -> 0
B45: =IFERROR(INDEX(Listas!$B$5:$B$40,MATCH(ROWS($B$39:B45),Listas!$E$5:$E$40,0)),"") -> Impostos (MEI / DAS) | C45: =IF($B45="","",SUMIFS(Lançamentos!$G$5:$G$1004,Lançamentos!$B$5:$B$1004,$B45,Lançamentos!$H$5:$H$1004,C$38)) -> 0 | D45: =IF($B45="","",SUMIFS(Lançamentos!$G$5:$G$1004,Lançamentos!$B$5:$B$1004,$B45,Lançamentos!$H$5:$H$1004,D$38)) -> 0 | E45: =IF($B45="","",SUMIFS(Lançamentos!$G$5:$G$1004,Lançamentos!$B$5:$B$1004,$B45,Lançamentos!$H$5:$H$1004,E$38)) -> 0 | F45: =IF($B45="","",SUMIFS(Lançamentos!$G$5:$G$1004,Lançamentos!$B$5:$B$1004,$B45,Lançamentos!$H$5:$H$1004,F$38)) -> 0 | G45: =IF($B45="","",SUMIFS(Lançamentos!$G$5:$G$1004,Lançamentos!$B$5:$B$1004,$B45,Lançamentos!$H$5:$H$1004,G$38)) -> 0 | H45: =IF($B45="","",SUMIFS(Lançamentos!$G$5:$G$1004,Lançamentos!$B$5:$B$1004,$B45,Lançamentos!$H$5:$H$1004,H$38)) -> 0 | I45: =IF($B45="","",SUMIFS(Lançamentos!$G$5:$G$1004,Lançamentos!$B$5:$B$1004,$B45,Lançamentos!$H$5:$H$1004,I$38)) -> 0 | J45: =IF($B45="","",SUMIFS(Lançamentos!$G$5:$G$1004,Lançamentos!$B$5:$B$1004,$B45,Lançamentos!$H$5:$H$1004,J$38)) -> 0 | ... N45: =IF($B45="","",SUMIFS(Lançamentos!$G$5:$G$1004,Lançamentos!$B$5:$B$1004,$B45,Lançamentos!$H$5:$H$1004,N$38)) -> 0 | O45: =IF($B45="","",SUM(C45:N45)) -> 0
B46: =IFERROR(INDEX(Listas!$B$5:$B$40,MATCH(ROWS($B$39:B46),Listas!$E$5:$E$40,0)),"") -> Taxas de pagamento | C46: =IF($B46="","",SUMIFS(Lançamentos!$G$5:$G$1004,Lançamentos!$B$5:$B$1004,$B46,Lançamentos!$H$5:$H$1004,C$38)) -> 0 | D46: =IF($B46="","",SUMIFS(Lançamentos!$G$5:$G$1004,Lançamentos!$B$5:$B$1004,$B46,Lançamentos!$H$5:$H$1004,D$38)) -> 0 | E46: =IF($B46="","",SUMIFS(Lançamentos!$G$5:$G$1004,Lançamentos!$B$5:$B$1004,$B46,Lançamentos!$H$5:$H$1004,E$38)) -> 0 | F46: =IF($B46="","",SUMIFS(Lançamentos!$G$5:$G$1004,Lançamentos!$B$5:$B$1004,$B46,Lançamentos!$H$5:$H$1004,F$38)) -> 0 | G46: =IF($B46="","",SUMIFS(Lançamentos!$G$5:$G$1004,Lançamentos!$B$5:$B$1004,$B46,Lançamentos!$H$5:$H$1004,G$38)) -> 0 | H46: =IF($B46="","",SUMIFS(Lançamentos!$G$5:$G$1004,Lançamentos!$B$5:$B$1004,$B46,Lançamentos!$H$5:$H$1004,H$38)) -> 0 | I46: =IF($B46="","",SUMIFS(Lançamentos!$G$5:$G$1004,Lançamentos!$B$5:$B$1004,$B46,Lançamentos!$H$5:$H$1004,I$38)) -> 0 | J46: =IF($B46="","",SUMIFS(Lançamentos!$G$5:$G$1004,Lançamentos!$B$5:$B$1004,$B46,Lançamentos!$H$5:$H$1004,J$38)) -> 0 | ... N46: =IF($B46="","",SUMIFS(Lançamentos!$G$5:$G$1004,Lançamentos!$B$5:$B$1004,$B46,Lançamentos!$H$5:$H$1004,N$38)) -> 0 | O46: =IF($B46="","",SUM(C46:N46)) -> 0
...

Sheet Tabela de preços
B1: Tabela de preços
B2: Os preços do catálogo, as horas que cada pacote toma e quanto sobra por hora. Mude preço e horas para testar.
B4: Seu valor-hora mínimo (R$) | C4: 60
B5: Imposto sobre o que recebe (%) | C5: 0
B7: Linha | C7: Pacote | D7: Preço (R$) | E7: Horas de trabalho | F7: Custos diretos (R$) | G7: Imposto (R$) | H7: Sobra (R$) | I7: Sobra por hora (R$) | J7: Situação
B8: Sites com pedido no WhatsApp | C8: Essencial | D8: 700 | E8: 8 | F8: 0 | G8: =D8*$C$5 -> 0 | H8: =D8-F8-G8 -> 700 | I8: =IF(E8>0,H8/E8,0) -> 87.5 | J8: =IF(I8>=$C$4,"Acima do mínimo","Abaixo do mínimo") -> Acima do mínimo
B9: Sites com pedido no WhatsApp | C9: Completo | D9: 1200 | E9: 16 | F9: 20 | G9: =D9*$C$5 -> 0 | H9: =D9-F9-G9 -> 1180 | I9: =IF(E9>0,H9/E9,0) -> 73.75 | J9: =IF(I9>=$C$4,"Acima do mínimo","Abaixo do mínimo") -> Acima do mínimo
B10: Sites com pedido no WhatsApp | C10: Premium | D10: 1900 | E10: 28 | F10: 40 | G10: =D10*$C$5 -> 0 | H10: =D10-F10-G10 -> 1860 | I10: =IF(E10>0,H10/E10,0) -> 66.428571 | J10: =IF(I10>=$C$4,"Acima do mínimo","Abaixo do mínimo") -> Acima do mínimo
B11: Lojas virtuais | C11: Loja Start | D11: 2500 | E11: 25 | F11: 0 | G11: =D11*$C$5 -> 0 | H11: =D11-F11-G11 -> 2500 | I11: =IF(E11>0,H11/E11,0) -> 100 | J11: =IF(I11>=$C$4,"Acima do mínimo","Abaixo do mínimo") -> Acima do mínimo
B12: Lojas virtuais | C12: Loja Pro | D12: 4500 | E12: 45 | F12: 0 | G12: =D12*$C$5 -> 0 | H12: =D12-F12-G12 -> 4500 | I12: =IF(E12>0,H12/E12,0) -> 100 | J12: =IF(I12>=$C$4,"Acima do mínimo","Abaixo do mínimo") -> Acima do mínimo
B13: Lojas virtuais | C13: Loja Sob Medida (a partir de) | D13: 7500 | E13: 80 | F13: 0 | G13: =D13*$C$5 -> 0 | H13: =D13-F13-G13 -> 7500 | I13: =IF(E13>0,H13/E13,0) -> 93.75 | J13: =IF(I13>=$C$4,"Acima do mínimo","Abaixo do mínimo") -> Acima do mínimo
B14: SaaS e sistemas | C14: Sistema MVP (a partir de) | D14: 6000 | E14: 80 | F14: 150 | G14: =D14*$C$5 -> 0 | H14: =D14-F14-G14 -> 5850 | I14: =IF(E14>0,H14/E14,0) -> 73.125 | J14: =IF(I14>=$C$4,"Acima do mínimo","Abaixo do mínimo") -> Acima do mínimo
B15: SaaS e sistemas | C15: SaaS Completo (a partir de) | D15: 15000 | E15: 200 | F15: 300 | G15: =D15*$C$5 -> 0 | H15: =D15-F15-G15 -> 14700 | I15: =IF(E15>0,H15/E15,0) -> 73.5 | J15: =IF(I15>=$C$4,"Acima do mínimo","Abaixo do mínimo") -> Acima do mínimo
B16: SaaS e sistemas | C16: Plataforma + IA (a partir de) | D16: 25000 | E16: 320 | F16: 600 | G16: =D16*$C$5 -> 0 | H16: =D16-F16-G16 -> 24400 | I16: =IF(E16>0,H16/E16,0) -> 76.25 | J16: =IF(I16>=$C$4,"Acima do mínimo","Abaixo do mínimo") -> Acima do mínimo
B17: Extras | C17: Página extra | D17: 250 | E17: 3 | F17: 0 | G17: =D17*$C$5 -> 0 | H17: =D17-F17-G17 -> 250 | I17: =IF(E17>0,H17/E17,0) -> 83.333333 | J17: =IF(I17>=$C$4,"Acima do mínimo","Abaixo do mínimo") -> Acima do mínimo
B18: Extras | C18: Animação exclusiva extra | D18: 350 | E18: 4 | F18: 0 | G18: =D18*$C$5 -> 0 | H18: =D18-F18-G18 -> 350 | I18: =IF(E18>0,H18/E18,0) -> 87.5 | J18: =IF(I18>=$C$4,"Acima do mínimo","Abaixo do mínimo") -> Acima do mínimo
B19: Extras | C19: Cadastro de 50 produtos | D19: 150 | E19: 2 | F19: 0 | G19: =D19*$C$5 -> 0 | H19: =D19-F19-G19 -> 150 | I19: =IF(E19>0,H19/E19,0) -> 75 | J19: =IF(I19>=$C$4,"Acima do mínimo","Abaixo do mínimo") -> Acima do mínimo
... B25: Mensalidades | C25: Hospedagem e suporte de sistemas (por mês) | D25: 400 | E25: 3 | F25: 150 | G25: =D25*$C$5 -> 0 | H25: =D25-F25-G25 -> 250 | I25: =IF(E25>0,H25/E25,0) -> 83.333333 | J25: =IF(I25>=$C$4,"Acima do mínimo","Abaixo do mínimo") -> Acima do mínimo
B28: Referências de mercado usadas para montar os preços (pesquisa de outubro de 2026)
B29: O quê | C29: Faixa | D29: Fonte
B30: Landing page, freelancer intermediário | C30: R$ 900 a R$ 2.500 | D30: bigdatauniversity.com.br/quanto-cobrar-por-uma-landing-page
B31: Loja Shopify ou Nuvemshop com tema e customização | C31: R$ 3.000 a R$ 8.000 | D31: freelasemcrise.com.br/quanto-cobrar/criar-loja-virtual
B32: MVP de SaaS feito por freelancer | C32: US$ 5 mil a US$ 20 mil | D32: we0.ai (guia de MVP para startups, 2026)
B33: Shopify Basic (plataforma) | C33: US$ 29/mês no anual · US$ 39 no mensal | D33: pt.shopify.com/pricing
B34: Domínio .com.br | C34: cerca de R$ 40 por ano | D34: registro.br (valor citado no site da Porta Studio)

Sheet Listas
B1: Listas
B2: Categorias e opções usadas nos menus. Para criar uma categoria nova, escreva no fim da lista e escolha o tipo.
B4: Categoria | C4: Tipo | D4: Nº entrada | E4: Nº saída | G4: Forma de pagamento | I4: Tipo de projeto | K4: Status do projeto | M4: Moeda | O4: Cobrança | Q4: Ativo?
B5: Site WhatsApp | C5: Entrada | D5: =IF(C5="Entrada",COUNTIF($C$5:C5,"Entrada"),"") -> 1 | E5: =IF(C5="Saída",COUNTIF($C$5:C5,"Saída"),"") | G5: Pix | I5: Site WhatsApp | K5: Orçamento | M5: R$ | O5: Mensal | Q5: Sim
B6: Loja virtual | C6: Entrada | D6: =IF(C6="Entrada",COUNTIF($C$5:C6,"Entrada"),"") -> 2 | E6: =IF(C6="Saída",COUNTIF($C$5:C6,"Saída"),"") | G6: Cartão de crédito | I6: Loja virtual | K6: Em produção | M6: US$ | O6: Anual | Q6: Não
B7: SaaS / sistema | C7: Entrada | D7: =IF(C7="Entrada",COUNTIF($C$5:C7,"Entrada"),"") -> 3 | E7: =IF(C7="Saída",COUNTIF($C$5:C7,"Saída"),"") | G7: Cartão de débito | I7: SaaS / sistema | K7: Entregue
B8: Mensalidade de cliente | C8: Entrada | D8: =IF(C8="Entrada",COUNTIF($C$5:C8,"Entrada"),"") -> 4 | E8: =IF(C8="Saída",COUNTIF($C$5:C8,"Saída"),"") | G8: Boleto | I8: Extras e ajustes | K8: Cancelado
B9: Extras e ajustes | C9: Entrada | D9: =IF(C9="Entrada",COUNTIF($C$5:C9,"Entrada"),"") -> 5 | E9: =IF(C9="Saída",COUNTIF($C$5:C9,"Saída"),"") | G9: Transferência
B10: Repasse de domínio | C10: Entrada | D10: =IF(C10="Entrada",COUNTIF($C$5:C10,"Entrada"),"") -> 6 | E10: =IF(C10="Saída",COUNTIF($C$5:C10,"Saída"),"") | G10: Dinheiro
B11: Outras entradas | C11: Entrada | D11: =IF(C11="Entrada",COUNTIF($C$5:C11,"Entrada"),"") -> 7 | E11: =IF(C11="Saída",COUNTIF($C$5:C11,"Saída"),"")
B12: Inteligência artificial | C12: Saída | D12: =IF(C12="Entrada",COUNTIF($C$5:C12,"Entrada"),"") | E12: =IF(C12="Saída",COUNTIF($C$5:C12,"Saída"),"") -> 1
B13: Domínios | C13: Saída | D13: =IF(C13="Entrada",COUNTIF($C$5:C13,"Entrada"),"") | E13: =IF(C13="Saída",COUNTIF($C$5:C13,"Saída"),"") -> 2
B14: Hospedagem | C14: Saída | D14: =IF(C14="Entrada",COUNTIF($C$5:C14,"Entrada"),"") | E14: =IF(C14="Saída",COUNTIF($C$5:C14,"Saída"),"") -> 3
B15: Shopify e plataformas | C15: Saída | D15: =IF(C15="Entrada",COUNTIF($C$5:C15,"Entrada"),"") | E15: =IF(C15="Saída",COUNTIF($C$5:C15,"Saída"),"") -> 4
B16: Ferramentas e apps | C16: Saída | D16: =IF(C16="Entrada",COUNTIF($C$5:C16,"Entrada"),"") | E16: =IF(C16="Saída",COUNTIF($C$5:C16,"Saída"),"") -> 5
B17: Anúncios e marketing | C17: Saída | D17: =IF(C17="Entrada",COUNTIF($C$5:C17,"Entrada"),"") | E17: =IF(C17="Saída",COUNTIF($C$5:C17,"Saída"),"") -> 6
B18: Impostos (MEI / DAS) | C18: Saída | D18: =IF(C18="Entrada",COUNTIF($C$5:C18,"Entrada"),"") | E18: =IF(C18="Saída",COUNTIF($C$5:C18,"Saída"),"") -> 7
B19: Taxas de pagamento | C19: Saída | D19: =IF(C19="Entrada",COUNTIF($C$5:C19,"Entrada"),"") | E19: =IF(C19="Saída",COUNTIF($C$5:C19,"Saída"),"") -> 8
B20: Freelancers e terceiros | C20: Saída | D20: =IF(C20="Entrada",COUNTIF($C$5:C20,"Entrada"),"") | E20: =IF(C20="Saída",COUNTIF($C$5:C20,"Saída"),"") -> 9
B21: Equipamentos | C21: Saída | D21: =IF(C21="Entrada",COUNTIF($C$5:C21,"Entrada"),"") | E21: =IF(C21="Saída",COUNTIF($C$5:C21,"Saída"),"") -> 10
B22: Internet e celular | C22: Saída | D22: =IF(C22="Entrada",COUNTIF($C$5:C22,"Entrada"),"") | E22: =IF(C22="Saída",COUNTIF($C$5:C22,"Saída"),"") -> 11
B23: Outras saídas | C23: Saída | D23: =IF(C23="Entrada",COUNTIF($C$5:C23,"Entrada"),"") | E23: =IF(C23="Saída",COUNTIF($C$5:C23,"Saída"),"") -> 12
D24: =IF(C24="Entrada",COUNTIF($C$5:C24,"Entrada"),"") | E24: =IF(C24="Saída",COUNTIF($C$5:C24,"Saída"),"")
D25: =IF(C25="Entrada",COUNTIF($C$5:C25,"Entrada"),"") | E25: =IF(C25="Saída",COUNTIF($C$5:C25,"Saída"),"")
D26: =IF(C26="Entrada",COUNTIF($C$5:C26,"Entrada"),"") | E26: =IF(C26="Saída",COUNTIF($C$5:C26,"Saída"),"")
D27: =IF(C27="Entrada",COUNTIF($C$5:C27,"Entrada"),"") | E27: =IF(C27="Saída",COUNTIF($C$5:C27,"Saída"),"")
D28: =IF(C28="Entrada",COUNTIF($C$5:C28,"Entrada"),"") | E28: =IF(C28="Saída",COUNTIF($C$5:C28,"Saída"),"")
D29: =IF(C29="Entrada",COUNTIF($C$5:C29,"Entrada"),"") | E29: =IF(C29="Saída",COUNTIF($C$5:C29,"Saída"),"")
D30: =IF(C30="Entrada",COUNTIF($C$5:C30,"Entrada"),"") | E30: =IF(C30="Saída",COUNTIF($C$5:C30,"Saída"),"")
D31: =IF(C31="Entrada",COUNTIF($C$5:C31,"Entrada"),"") | E31: =IF(C31="Saída",COUNTIF($C$5:C31,"Saída"),"")
D32: =IF(C32="Entrada",COUNTIF($C$5:C32,"Entrada"),"") | E32: =IF(C32="Saída",COUNTIF($C$5:C32,"Saída"),"")
D33: =IF(C33="Entrada",COUNTIF($C$5:C33,"Entrada"),"") | E33: =IF(C33="Saída",COUNTIF($C$5:C33,"Saída"),"")
D34: =IF(C34="Entrada",COUNTIF($C$5:C34,"Entrada"),"") | E34: =IF(C34="Saída",COUNTIF($C$5:C34,"Saída"),"")
D35: =IF(C35="Entrada",COUNTIF($C$5:C35,"Entrada"),"") | E35: =IF(C35="Saída",COUNTIF($C$5:C35,"Saída"),"")
... D40: =IF(C40="Entrada",COUNTIF($C$5:C40,"Entrada"),"") | E40: =IF(C40="Saída",COUNTIF($C$5:C40,"Saída"),"")
